<mujoco model="acrobot">
    <compiler inertiafromgeom="true" coordinate="local"/>
    <default>
        <joint damping="1e-1" />
        <!-- <motor forcerange="-.1 .1"/> -->
        <motor ctrllimited="true" ctrlrange="-1 1"/>
</default>

    <option timestep="0.01" gravity="0 0 -9.81" >
        <flag contact="disable" energy="disable"/>
    </option>

    <size nstack="4000" />

    <asset>
        <texture name="texplane" type="2d" builtin="checker" rgb1=".2 .3 .4" rgb2=".1 0.15 0.2" 
            width="512" height="512"/>  
        <material name='MatPlane' reflectance='0.3' texture="texplane" texrepeat="1 1" texuniform="true"/>
    </asset>

    <worldbody>
        <light mode='targetbodycom' target='upper_arm' directional='false' diffuse='.8 .8 .8' specular='0.3 0.3 0.3' pos='0 0 4.0' dir='0 0 -1'/>
        <geom name='floor' pos='0 0 -0.2' size='5 5 .125' type='plane' material="MatPlane" />
        <geom name="rail" type="capsule" fromto="0.5 0 1 -0.5 0 1" size="0.01 0.5" rgba="0.7 0.7 0.7 1" />
        <body name="upper_arm" pos="0 0 1">
            <joint name="shoulder" type="hinge" pos="0 0 0" axis="1 0 0" />
            <geom name="upper_arm" type="capsule" fromto="0 0 0 0 0 0.5" size="0.049 0.3" rgba="0 0.7 0.7 1" />
            <body name="lower_arm" pos="0 0 .5">
                <joint name="elbow" type="hinge" pos="0 0 0" axis="1 0 0"/>
                <geom name="lower_arm" type="capsule" fromto="0 0 0 0 1e-6 0.5" size="0.049 0.3" rgba="0.7 0.7 0 1" />
                <site name="tip" pos="0 0 .5"/>         
            </body>
        </body>
    </worldbody>

    <actuator>
       <!--<motor name="shoulder" joint="shoulder" gear="30"/>-->
       <motor name="shoulder" joint="shoulder" gear="30"/>
        <motor name="elbow" joint="elbow" gear="20"/>
    </actuator>

    <sensor>
        <jointpos name='shoulder_pos' joint='shoulder' />
        <jointpos name='shoulder_pos1' joint='shoulder' />
        <jointpos name='elbow_pos'    joint='elbow' />
        <jointpos name='elbow_pos1'    joint='elbow' />

        <jointvel name='shoulder_vel' joint='shoulder' />
        <jointvel name='elbow_vel'    joint='elbow' />

        <!--
        <framepos name='tip' objtype='site' objname='tip' />
-->
    </sensor>
</mujoco>
